Waiting for PostgreSQL...


db:5432 - accepting connections


PostgreSQL is ready!


Running migrations...


Traceback (most recent call last):


File "/app/manage.py", line 22, in <module>


main()


File "/app/manage.py", line 18, in main


execute_from_command_line(sys.argv)


File "/usr/local/lib/python3.12/site-packages/django/core/management/__init__.py", line 442, in execute_from_command_line


utility.execute()


File "/usr/local/lib/python3.12/site-packages/django/core/management/__init__.py", line 436, in execute


self.fetch_command(subcommand).run_from_argv(self.argv)


File "/usr/local/lib/python3.12/site-packages/django/core/management/base.py", line 416, in run_from_argv


self.execute(*args, **cmd_options)


File "/usr/local/lib/python3.12/site-packages/django/core/management/base.py", line 457, in execute


self.check(**check_kwargs)


File "/usr/local/lib/python3.12/site-packages/django/core/management/base.py", line 492, in check


all_issues = checks.run_checks(


^^^^^^^^^^^^^^^^^^


File "/usr/local/lib/python3.12/site-packages/django/core/checks/registry.py", line 89, in run_checks


new_errors = check(app_configs=app_configs, databases=databases)


^^^^^^^^^^^^^^^^^^^^^^^^^^^^^^^^^^^^^^^^^^^^^^^^^^^


File "/usr/local/lib/python3.12/site-packages/django/core/checks/urls.py", line 44, in check_url_namespaces_unique


all_namespaces = _load_all_namespaces(resolver)


^^^^^^^^^^^^^^^^^^^^^^^^^^^^^^


File "/usr/local/lib/python3.12/site-packages/django/core/checks/urls.py", line 63, in _load_all_namespaces


url_patterns = getattr(resolver, "url_patterns", [])


^^^^^^^^^^^^^^^^^^^^^^^^^^^^^^^^^^^^^


File "/usr/local/lib/python3.12/site-packages/django/utils/functional.py", line 47, in __get__


res = instance.__dict__[self.name] = self.func(instance)


^^^^^^^^^^^^^^^^^^^


File "/usr/local/lib/python3.12/site-packages/django/urls/resolvers.py", line 718, in url_patterns


patterns = getattr(self.urlconf_module, "urlpatterns", self.urlconf_module)


^^^^^^^^^^^^^^^^^^^


File "/usr/local/lib/python3.12/site-packages/django/utils/functional.py", line 47, in __get__


res = instance.__dict__[self.name] = self.func(instance)


^^^^^^^^^^^^^^^^^^^


File "/usr/local/lib/python3.12/site-packages/django/urls/resolvers.py", line 711, in urlconf_module


return import_module(self.urlconf_name)


^^^^^^^^^^^^^^^^^^^^^^^^^^^^^^^^


File "/usr/local/lib/python3.12/importlib/__init__.py", line 90, in import_module


return _bootstrap._gcd_import(name[level:], package, level)


^^^^^^^^^^^^^^^^^^^^^^^^^^^^^^^^^^^^^^^^^^^^^^^^^^^^


File "<frozen importlib._bootstrap>", line 1387, in _gcd_import


File "<frozen importlib._bootstrap>", line 1360, in _find_and_load


File "<frozen importlib._bootstrap>", line 1331, in _find_and_load_unlocked


File "<frozen importlib._bootstrap>", line 935, in _load_unlocked


File "<frozen importlib._bootstrap_external>", line 999, in exec_module


File "<frozen importlib._bootstrap>", line 488, in _call_with_frames_removed


File "/app/config/urls.py", line 24, in <module>


path('api/sample/', include('apps.sample.urls')),


^^^^^^^^^^^^^^^^^^^^^^^^^^^


File "/usr/local/lib/python3.12/site-packages/django/urls/conf.py", line 39, in include