Waiting for PostgreSQL...


db:5432 - accepting connections


PostgreSQL is ready!


Running migrations...


Traceback (most recent call last):


File "/usr/local/lib/python3.12/site-packages/django/apps/config.py", line 235, in get_model


return self.models[model_name.lower()]


~~~~~~~~~~~^^^^^^^^^^^^^^^^^^^^


KeyError: 'user'




During handling of the above exception, another exception occurred:




Traceback (most recent call last):


File "/usr/local/lib/python3.12/site-packages/django/contrib/auth/__init__.py", line 283, in get_user_model


return django_apps.get_model(settings.AUTH_USER_MODEL, require_ready=False)


^^^^^^^^^^^^^^^^^^^^^^^^^^^^^^^^^^^^^^^^^^^^^^^^^^^^^^^^^^^^^^^^^^^^


File "/usr/local/lib/python3.12/site-packages/django/apps/registry.py", line 213, in get_model


return app_config.get_model(model_name, require_ready=require_ready)


^^^^^^^^^^^^^^^^^^^^^^^^^^^^^^^^^^^^^^^^^^^^^^^^^^^^^^^^^^^^^


File "/usr/local/lib/python3.12/site-packages/django/apps/config.py", line 237, in get_model


raise LookupError(


LookupError: App 'users' doesn't have a 'User' model.




During handling of the above exception, another exception occurred:




Traceback (most recent call last):


File "/app/manage.py", line 22, in <module>


main()


File "/app/manage.py", line 18, in main


execute_from_command_line(sys.argv)


File "/usr/local/lib/python3.12/site-packages/django/core/management/__init__.py", line 442, in execute_from_command_line


utility.execute()


File "/usr/local/lib/python3.12/site-packages/django/core/management/__init__.py", line 416, in execute


django.setup()


File "/usr/local/lib/python3.12/site-packages/django/__init__.py", line 24, in setup


apps.populate(settings.INSTALLED_APPS)


File "/usr/local/lib/python3.12/site-packages/django/apps/registry.py", line 124, in populate


app_config.ready()


File "/usr/local/lib/python3.12/site-packages/django/contrib/admin/apps.py", line 27, in ready


self.module.autodiscover()


File "/usr/local/lib/python3.12/site-packages/django/contrib/admin/__init__.py", line 52, in autodiscover


autodiscover_modules("admin", register_to=site)


File "/usr/local/lib/python3.12/site-packages/django/utils/module_loading.py", line 58, in autodiscover_modules


import_module("%s.%s" % (app_config.name, module_to_search))


File "/usr/local/lib/python3.12/importlib/__init__.py", line 90, in import_module


return _bootstrap._gcd_import(name[level:], package, level)


^^^^^^^^^^^^^^^^^^^^^^^^^^^^^^^^^^^^^^^^^^^^^^^^^^^^


File "<frozen importlib._bootstrap>", line 1387, in _gcd_import


File "<frozen importlib._bootstrap>", line 1360, in _find_and_load


File "<frozen importlib._bootstrap>", line 1331, in _find_and_load_unlocked


File "<frozen importlib._bootstrap>", line 935, in _load_unlocked


File "<frozen importlib._bootstrap_external>", line 999, in exec_module


File "<frozen importlib._bootstrap>", line 488, in _call_with_frames_removed


File "/usr/local/lib/python3.12/site-packages/django/contrib/auth/admin.py", line 6, in <module>