File "/usr/local/lib/python3.12/importlib/__init__.py", line 90, in import_module


return _bootstrap._gcd_import(name[level:], package, level)


^^^^^^^^^^^^^^^^^^^^^^^^^^^^^^^^^^^^^^^^^^^^^^^^^^^^


File "<frozen importlib._bootstrap>", line 1387, in _gcd_import


File "<frozen importlib._bootstrap>", line 1360, in _find_and_load


File "<frozen importlib._bootstrap>", line 1331, in _find_and_load_unlocked


File "<frozen importlib._bootstrap>", line 935, in _load_unlocked


File "<frozen importlib._bootstrap_external>", line 999, in exec_module


File "<frozen importlib._bootstrap>", line 488, in _call_with_frames_removed


File "/usr/local/lib/python3.12/site-packages/django/contrib/auth/admin.py", line 6, in <module>


from django.contrib.auth.forms import (


File "/usr/local/lib/python3.12/site-packages/django/contrib/auth/forms.py", line 20, in <module>


UserModel = get_user_model()


^^^^^^^^^^^^^^^^


File "/usr/local/lib/python3.12/site-packages/django/contrib/auth/__init__.py", line 289, in get_user_model


raise ImproperlyConfigured(


django.core.exceptions.ImproperlyConfigured: AUTH_USER_MODEL refers to model 'users.User' that has not been installed


[2025-10-27 18:34:48 +0900] [11] [INFO] Worker exiting (pid: 11)


[2025-10-27 09:34:48 +0000] [1] [ERROR] Worker (pid:11) exited with code 3


Traceback (most recent call last):


File "/usr/local/lib/python3.12/site-packages/gunicorn/arbiter.py", line 208, in run


self.sleep()


File "/usr/local/lib/python3.12/site-packages/gunicorn/arbiter.py", line 359, in sleep


ready = select.select([self.PIPE[0]], [], [], 1.0)


^^^^^^^^^^^^^^^^^^^^^^^^^^^^^^^^^^^^^^^^^^


File "/usr/local/lib/python3.12/site-packages/gunicorn/arbiter.py", line 241, in handle_chld


self.reap_workers()


File "/usr/local/lib/python3.12/site-packages/gunicorn/arbiter.py", line 529, in reap_workers


raise HaltServer(reason, self.WORKER_BOOT_ERROR)


gunicorn.errors.HaltServer: <HaltServer 'Worker failed to boot.' 3>




During handling of the above exception, another exception occurred:




Traceback (most recent call last):


File "/usr/local/bin/gunicorn", line 7, in <module>


sys.exit(run())


^^^^^


File "/usr/local/lib/python3.12/site-packages/gunicorn/app/wsgiapp.py", line 66, in run


WSGIApplication("%(prog)s [OPTIONS] [APP_MODULE]", prog=prog).run()


File "/usr/local/lib/python3.12/site-packages/gunicorn/app/base.py", line 235, in run


super().run()


File "/usr/local/lib/python3.12/site-packages/gunicorn/app/base.py", line 71, in run


Arbiter(self).run()


File "/usr/local/lib/python3.12/site-packages/gunicorn/arbiter.py", line 228, in run


self.halt(reason=inst.reason, exit_status=inst.exit_status)


File "/usr/local/lib/python3.12/site-packages/gunicorn/arbiter.py", line 341, in halt


self.stop()


File "/usr/local/lib/python3.12/site-packages/gunicorn/arbiter.py", line 395, in stop


time.sleep(0.1)


File "/usr/local/lib/python3.12/site-packages/gunicorn/arbiter.py", line 241, in handle_chld


self.reap_workers()


File "/usr/local/lib/python3.12/site-packages/gunicorn/arbiter.py", line 529, in reap_workers


raise HaltServer(reason, self.WORKER_BOOT_ERROR)


gunicorn.errors.HaltServer: <HaltServer 'Worker failed to boot.' 3>