File "/usr/local/lib/python3.12/site-packages/django/db/models/base.py", line 196, in __new__


new_class.add_to_class(obj_name, obj)


File "/usr/local/lib/python3.12/site-packages/django/db/models/base.py", line 373, in add_to_class


value.contribute_to_class(cls, name)


File "/usr/local/lib/python3.12/site-packages/django/db/models/fields/related.py", line 928, in contribute_to_class


super().contribute_to_class(cls, name, private_only=private_only, **kwargs)


File "/usr/local/lib/python3.12/site-packages/django/db/models/fields/related.py", line 380, in contribute_to_class


lazy_related_operation(


File "/usr/local/lib/python3.12/site-packages/django/db/models/fields/related.py", line 88, in lazy_related_operation


return apps.lazy_model_operation(partial(function, **kwargs), *model_keys)


^^^^^^^^^^^^^^^^^^^^^^^^^^^^^^^^^^^^^^^^^^^^^^^^^^^^^^^^^^^^^^^^^^^


File "/usr/local/lib/python3.12/site-packages/django/db/models/fields/related.py", line 86, in <genexpr>


model_keys = (make_model_tuple(m) for m in models)


^^^^^^^^^^^^^^^^^^^


File "/usr/local/lib/python3.12/site-packages/django/db/models/utils.py", line 22, in make_model_tuple


raise ValueError(


ValueError: Invalid model reference 'apps.users.User'. String model references must be of the form 'app_label.ModelName'.


[2025-10-27 18:25:04 +0900] [11] [INFO] Worker exiting (pid: 11)


[2025-10-27 09:25:04 +0000] [1] [ERROR] Worker (pid:11) exited with code 3


Traceback (most recent call last):


File "/usr/local/lib/python3.12/site-packages/gunicorn/arbiter.py", line 208, in run


self.sleep()


File "/usr/local/lib/python3.12/site-packages/gunicorn/arbiter.py", line 359, in sleep


ready = select.select([self.PIPE[0]], [], [], 1.0)


^^^^^^^^^^^^^^^^^^^^^^^^^^^^^^^^^^^^^^^^^^


File "/usr/local/lib/python3.12/site-packages/gunicorn/arbiter.py", line 241, in handle_chld


self.reap_workers()


File "/usr/local/lib/python3.12/site-packages/gunicorn/arbiter.py", line 529, in reap_workers


raise HaltServer(reason, self.WORKER_BOOT_ERROR)


gunicorn.errors.HaltServer: <HaltServer 'Worker failed to boot.' 3>




During handling of the above exception, another exception occurred:




Traceback (most recent call last):


File "/usr/local/bin/gunicorn", line 7, in <module>


sys.exit(run())


^^^^^


File "/usr/local/lib/python3.12/site-packages/gunicorn/app/wsgiapp.py", line 66, in run


WSGIApplication("%(prog)s [OPTIONS] [APP_MODULE]", prog=prog).run()


File "/usr/local/lib/python3.12/site-packages/gunicorn/app/base.py", line 235, in run


super().run()


File "/usr/local/lib/python3.12/site-packages/gunicorn/app/base.py", line 71, in run


Arbiter(self).run()


File "/usr/local/lib/python3.12/site-packages/gunicorn/arbiter.py", line 228, in run


self.halt(reason=inst.reason, exit_status=inst.exit_status)


File "/usr/local/lib/python3.12/site-packages/gunicorn/arbiter.py", line 341, in halt


self.stop()


File "/usr/local/lib/python3.12/site-packages/gunicorn/arbiter.py", line 395, in stop


time.sleep(0.1)


File "/usr/local/lib/python3.12/site-packages/gunicorn/arbiter.py", line 241, in handle_chld


self.reap_workers()


File "/usr/local/lib/python3.12/site-packages/gunicorn/arbiter.py", line 529, in reap_workers


raise HaltServer(reason, self.WORKER_BOOT_ERROR)


gunicorn.errors.HaltServer: <HaltServer 'Worker failed to boot.' 3>